Workbook
Name ABEILLE: 'CT à Transf'!$AA$16:$BI$16
Name AFER: 'CT à Transf'!$AA$17:$BI$17
Name AG2R_LA_MONDIALE: 'CT à Transf'!$AA$18:$BI$18
Name AGEAS: 'CT à Transf'!$AA$19:$BI$19
Name AGIPI: 'CT à Transf'!$AA$20:$BI$20
Name ALLIANZ: 'CT à Transf'!$AA$21:$BI$21
Name ALPTIS: 'CT à Transf'!$AA$22:$BI$22
Name APICIL: 'CT à Transf'!$AA$23:$BI$23
Name APRIL: 'CT à Transf'!$AA$24:$BI$24
Name AREAS: 'CT à Transf'!$AA$25:$BI$25
Name AXA: 'CT à Transf'!$AA$26:$BI$26
Name BANQUE_POPULAIRE: 'CT à Transf'!$AA$27:$BI$27
Name BNP: 'CT à Transf'!$AA$28:$BI$28
Name CAISSE_D_EPARGNE: 'CT à Transf'!$AA$29:$BI$29
Name CARDIF: 'CT à Transf'!$AA$30:$BI$30
Name Celibataire_Veuf_Divorce: MEPPER2!$E$32
Name Compagnies: 'CT à Transf'!$Z$16:$Z$68
Name CREDIT_AGRICOLE: 'CT à Transf'!$AA$31:$BI$31
Name CREDIT_DU_NORD: 'CT à Transf'!$AA$32:$BI$32
Name CREDIT_MUTUEL: 'CT à Transf'!$AA$33:$BI$33
Name EPSENS: 'CT à Transf'!$AA$34:$BI$34
Name EPSOR: 'CT à Transf'!$AA$35:$BI$35
Name ERES: 'CT à Transf'!$AA$36:$BI$36
Name GAN: 'CT à Transf'!$AA$37:$BI$37
Name GARANCE: 'CT à Transf'!$AA$38:$BI$38
Name GENERALI: 'CT à Transf'!$AA$39:$BI$39
Name GO_EPARGNE: 'CT à Transf'!$AA$40:$BI$40
Name GROUPAMA: 'CT à Transf'!$AA$41:$BI$41
Name HARMONIE_MUTUELLE: 'CT à Transf'!$AA$42:$BI$42
Name HSBC: 'CT à Transf'!$AA$43:$BI$43
Name LA_BANQUE_POSTALE: 'CT à Transf'!$AA$44:$BI$44
Name LA_MEDICALE: 'CT à Transf'!$AA$45:$BI$45
Name LCL: 'CT à Transf'!$AA$46:$BI$46
Name LPA: 'CT à Transf'!$AA$47:$BI$47
Name MAAF: 'CT à Transf'!$AA$48:$BI$48
Name MACIF: 'CT à Transf'!$AA$49:$BI$49
Name MACSF: 'CT à Transf'!$AA$50:$BI$50
Name MAIF: 'CT à Transf'!$AA$51:$BI$51
Name MALAKOFF_HUMANIS: 'CT à Transf'!$AA$52:$BI$52
Name MAPA: 'CT à Transf'!$AA$53:$BI$53
Name Marie_Pacse: MEPPER2!$E$31:$F$31
Name MATMUT: 'CT à Transf'!$AA$54:$BI$54
Name MEDICIS: 'CT à Transf'!$AA$55:$BI$55
Name MMA: 'CT à Transf'!$AA$56:$BI$56
Name MNRA: 'CT à Transf'!$AA$57:$BI$57
Name NORTIA: 'CT à Transf'!$AA$58:$BI$58
Name OK: TRUE
Name ORADEA: 'CT à Transf'!$AA$59:$BI$59
Name PREFON: 'CT à Transf'!$AA$60:$BI$60
Name PREVOIR: 'CT à Transf'!$AA$61:$BI$61
Name PRIMONIAL: 'CT à Transf'!$AA$62:$BI$62
Name PRO_BTP: 'CT à Transf'!$AA$63:$BI$63
Name Situation: MEPPER2!$D$31:$D$32
Name SMA: 'CT à Transf'!$AA$64:$BI$64
Name SOCIETE_GENERALE: 'CT à Transf'!$AA$65:$BI$65
Name SWISSLIFE: 'CT à Transf'!$AA$66:$BI$66
Name UFF: 'CT à Transf'!$AA$67:$BI$67
Name UMR: 'CT à Transf'!$AA$68:$BI$68

Sheet Login
S1: 122

Sheet Home
B5: =TODAY() -> 46023

Sheet Données
E4: Barème | F4: =YEAR(TODAY()) -> 2026 | Q4: Zoom écran : | R4: 95
B5: =TODAY() -> 46023 | E5: Sur revenus | F5: =F4-1 -> 2025 | Q5: Fin de validité : | R5: 46023
Q6: Date du jour : | R6: =TODAY() -> 46023
F12: Taux | G12: Retraitement | N12: Seuil | P12: Seul | Q12: Couple
D13: 0 | E13: 11498 | F13: 0 | K13: Abattement 1 | L13: 152500 | N13: 250000 | P13: 0 | Q13: 0
D14: =E13+1 -> 11499 | E14: 29315 | F14: 0.11 | G14: =E13*F14 -> 1264.78 | K14: Abattement 2 | L14: 30500 | N14: 500000 | P14: 0.03 | Q14: 0
D15: =E14+1 -> 29316 | E15: 83823 | F15: 0.3 | G15: =(E13-D13)*F15+(E14-E13)*(F15-F14) -> 6834.63 | K15: Fisca > 8 ans | L15: 0.075 | N15: 1000000 | P15: 0.04 | Q15: 0.03
D16: =E15+1 -> 83824 | E16: 180294 | F16: 0.41 | G16: =(E13-D13)*F16+(E14-E13)*(F16-F14)+(E15-E14)*(F16-F15) -> 16055.16 | K16: 152500 | L16: 0.2 | N16: Plus | P16: 0.04 | Q16: 0.04
D17: =E16 -> 180294 | F17: 0.45 | G17: =(E13-D13)*F17+(E14-E13)*(F17-F14)+(E15-E14)*(F17-F15)+(E16-E15)*(F17-F16) -> 23266.92 | K17: 700000 | L17: 0.3125
D18: Plafond du quotient familial | F18: 1791 | G18: 4224 | H18: parents isolés (deux 1ere parts)
D19: Décote (Célib/couple) | E19: Déclenchement | F19: 1964 | G19: 3248
E20: Montant | F20: 889 | G20: 1470
E21: Taux | F21: 0.4525
D22: Exemple Calcul de décote 2023 pour un célibataire : 833 – 45.25 % de l’impôt
F23: =F4 -> 2026 | H23: =F5 -> 2025
D24: Plafond abattement 10% | F24: 14426 | G24: 504 | H24: 14171 | I24: 495 | K24: IS | L24: 0.25
D25: Plafond abt 10% retraités | F25: 4399 | G25: 450 | H25: 4321 | I25: 442 | K25: IS réduit | L25: 0.15
K26: Seuil IS réduit | L26: 42500 | N26: Seuil sortie capital (PERP, Madelin, Art83) (rente mensuelle) | S26: 110
N27: PFL pour capital PERP | S27: 0.075
D28: PFU | F28: 0.128
F35: PS | G35: Deductible
D36: PS (patrimoine et capital) | F36: 0.172 | G36: 0.068
D37: PS sur retraite | E37: Revenu fiscal de ref | G37: ="+/0,25 parts" -> +/0,25 parts | H37: CSG | I37: CRDS | J37: CASA | K37: Maladie | L37: Total | M37: CSG déd
D38: 1 part | E38: 0 | F38: 11432 | G38: 1526 | H38: exo | I38: exo | J38: exo | K38: exo | L38: =0 -> 0 | M38: 0
E39: =F38+1 -> 11433 | F39: 14944 | G39: 1995 | H39: 0.038 | I39: 0.005 | J39: exo | K39: exo | L39: =H39+I39 -> 0.043 | M39: 0.038
E40: =F39+1 -> 14945 | F40: 23193 | G40: 3095.5 | H40: 0.066 | I40: 0.005 | J40: 0.003 | K40: 0.01 | L40: =H40+I40+J40+K40 -> 0.084 | M40: 0.042
E41: =F40 -> 23193 | H41: 0.083 | I41: 0.005 | J41: 0.003 | K41: 0.01 | L41: =H41+I41+J41+K41 -> 0.101 | M41: 0.059
D49: Historique plafonds sécurité sociale | H49: Type de produit | L49: Divers
D50: 2019 | E50: 40524 | F50: Ne pas étendre cette liste, remplacer du plus ancien au plus récent | H50: Madelin (154 bis CGI) | L50: Marié/pacsé | M50: Situation familiale
D51: 2020 | E51: 41136 | H51: Art 83 CGI | L51: Célibataire/veuf/divorcé
D52: 2021 | E52: 41136 | H52: PERin (154 bis CGI) | L52: Rente Réversible | M52: Type de rente
D53: 2022 | E53: 41136 | H53: PERin (163 Quater CGI) | L53: Rente Non réversible
D54: 2023 | E54: 43992 | H54: PERin non déduit | L54: selon les hypothèses des contrats | M54: Type projection rente
D55: 2024 | E55: 46368 | H55: PERob (Art83 CGI) | L55: sur mesure
D56: 2025 | E56: 47100 | H56: PERP et assimilés
H57: PERCO/PEReco
H58: Assurance vie

Sheet Placement
B5: =TODAY() -> 46023
E12: Placement 1 | F12: Placement 2 | G12: Placement 3 | H12: Assurance vie | J12: Compte titre
H13: SCPI | I13: Produit strucutré distri
D14: Rendement Net de FG | E14: 0.05 | F14: 0.05 | G14: 0.04 | H14: 0.035 | I14: 0.04 | J14: 0.05
D16: Placement Initial | E16: 563750 | F16: 570000 | G16: 100000 | H16: 97000 | I16: 100000 | J16: 100000
D17: Frais d'entrée | G17: 0.03 | H17: 0.085 | I17: 0
D18: Année 1 | E18: =(PRODUCT((E16-(E16*E17)),(POWER($E$14,1))))+(E16-(E16*E17)) -> 591937.5 | F18: =(PRODUCT((F16-(F16*F17)),(POWER($F$14,1))))+(F16-(F16*F17)) -> 598500 | G18: =(PRODUCT((G16-(G16*G17)),(POWER(G14,1))))+(G16-(G16*G17)) -> 100880 | H18: =(PRODUCT(H16,(POWER(H14,1))))+(H16-(H16*H17)) -> 92150 | I18: =(I16-(I16*I17))+(I14*(I16-(I16*I17))) -> 104000 | J18: =(J16-(J16*J17))+(J14*(J16-(J16*J17))) -> 105000
D19: Année 2 | E19: =(PRODUCT(E18,(POWER($E$14,1))))+E18 -> 621534.38 | F19: =(PRODUCT(F18,(POWER($F$14,1))))+F18 -> 628425 | G19: =(PRODUCT(G18,(POWER($G$14,1))))+G18 -> 104915.2 | H19: =(PRODUCT($H$16,(POWER($H$14,1))))+H18 -> 95545 | I19: =(I16-(I16*I17))+((I16-(I16*I17))*$I$14*2) -> 108000 | J19: =(J16-(J16*J17))+((J16-(J16*J17))*J14*2) -> 110000
D20: Année 3 | E20: =(PRODUCT(E19,(POWER($E$14,1))))+E19 -> 652611.09 | F20: =(PRODUCT(F19,(POWER($F$14,1))))+F19 -> 659846.25 | G20: =(PRODUCT(G19,(POWER($G$14,1))))+G19 -> 109111.81 | H20: =(PRODUCT($H$16,(POWER($H$14,1))))+H19 -> 98940 | I20: =(I16-(I16*I17))+((I16-(I16*I17))*I14*3) -> 112000 | J20: =(J16-(J16*J17))+((J16-(J16*J17))*J14*3) -> 115000
D21: Année 4 | E21: =(PRODUCT(E20,(POWER($E$14,1))))+E20 -> 685241.65 | F21: =(PRODUCT(F20,(POWER($F$14,1))))+F20 -> 692838.56 | G21: =(PRODUCT(G20,(POWER($G$14,1))))+G20 -> 113476.28 | H21: =(PRODUCT($H$16,(POWER($H$14,1))))+H20 -> 102335 | I21: =(I16-(I16*I17))+((I16-(I16*I17))*I14*4) -> 116000 | J21: =(J16-(J16*J17))+((J16-(J16*J17))*J14*4) -> 120000
D22: Année 5 | E22: =(PRODUCT(E21,(POWER($E$14,1))))+E21 -> 719503.73 | F22: =(PRODUCT(F21,(POWER($F$14,1))))+F21 -> 727480.49 | G22: =(PRODUCT(G21,(POWER($G$14,1))))+G21 -> 118015.33 | H22: =(PRODUCT($H$16,(POWER($H$14,1))))+H21 -> 105730 | I22: =(I16-(I16*I17))+((I16-(I16*I17))*I14*5) -> 120000 | J22: =(J16-(J16*J17))+((J16-(J16*J17))*J14*5) -> 125000
D23: Année 6 | E23: =(PRODUCT(E22,(POWER($E$14,1))))+E22 -> 755478.92 | F23: =(PRODUCT(F22,(POWER($F$14,1))))+F22 -> 763854.52 | G23: =(PRODUCT(G22,(POWER($G$14,1))))+G22 -> 122735.94 | H23: =(PRODUCT($H$16,(POWER($H$14,1))))+H22 -> 109125 | I23: =(I16-(I16*I17))+((I16-(I16*I17))*I14*6) -> 124000 | J23: =(J16-(J16*J17))+((J16-(J16*J17))*J14*6) -> 130000
D24: Année 7 | E24: =(PRODUCT(E23,(POWER($E$14,1))))+E23 -> 793252.86 | F24: =(PRODUCT(F23,(POWER($F$14,1))))+F23 -> 802047.24 | G24: =(PRODUCT(G23,(POWER($G$14,1))))+G23 -> 127645.38 | H24: =(PRODUCT($H$16,(POWER($H$14,1))))+H23 -> 112520 | I24: =(I16-(I16*I17))+((I16-(I16*I17))*I14*7) -> 128000 | J24: =(J16-(J16*J17))+((J16-(J16*J17))*J14*7) -> 135000
D25: Année 8 | E25: =(PRODUCT(E24,(POWER($E$14,1))))+E24 -> 832915.51 | F25: =(PRODUCT(F24,(POWER($F$14,1))))+F24 -> 842149.6 | G25: =(PRODUCT(G24,(POWER($G$14,1))))+G24 -> 132751.2 | H25: =(PRODUCT(H16,(POWER(H14,1))))+H24 -> 115915 | I25: =(I16-(I16*I17))+((I16-(I16*I17))*I14*8) -> 132000 | J25: =(J16-(J16*J17))+((J16-(J16*J17))*J14*8) -> 140000
D26: Année 9 | E26: =(PRODUCT(E25,(POWER($E$14,1))))+E25 -> 874561.28 | F26: =(PRODUCT(F25,(POWER($F$14,1))))+F25 -> 884257.08 | G26: =(PRODUCT(G25,(POWER($G$14,1))))+G25 -> 138061.25 | H26: =(PRODUCT($H$16,(POWER($H$14,1))))+H25 -> 119310 | I26: =(I16-(I16*I17))+((I16-(I16*I17))*I14*9) -> 136000 | J26: =(J16-(J16*J17))+((J16-(J16*J17))*J14*9) -> 145000
D27: Année 10 | E27: =(PRODUCT(E26,(POWER($E$14,1))))+E26 -> 918289.35 | F27: =(PRODUCT(F26,(POWER($F$14,1))))+F26 -> 928469.94 | G27: =(PRODUCT(G26,(POWER($G$14,1))))+G26 -> 143583.7 | H27: =(PRODUCT($H$16,(POWER($H$14,1))))+H26 -> 122705 | I27: =(I16-(I16*I17))+((I16-(I16*I17))*I14*10) -> 140000 | J27: =(J16-(J16*J17))+((J16-(J16*J17))*J14*10) -> 150000
D28: Année 11 | E28: =(PRODUCT(E27,(POWER($E$14,1))))+E27 -> 964203.81 | F28: =(PRODUCT(F27,(POWER($F$14,1))))+F27 -> 974893.43 | G28: =(PRODUCT(G27,(POWER($G$14,1))))+G27 -> 149327.04 | H28: =(PRODUCT($H$16,(POWER($H$14,1))))+H27 -> 126100
D29: Année 12 | E29: =(PRODUCT(E28,(POWER($E$14,1))))+E28 -> 1012414 | F29: =(PRODUCT(F28,(POWER($F$14,1))))+F28 -> 1023638.1 | G29: =(PRODUCT(G28,(POWER($G$14,1))))+G28 -> 155300.13 | H29: =(PRODUCT($H$16,(POWER($H$14,1))))+H28 -> 129495
D30: Année 13 | E30: =(PRODUCT(E29,(POWER($E$14,1))))+E29 -> 1063034.7 | F30: =(PRODUCT(F29,(POWER($F$14,1))))+F29 -> 1074820 | G30: =(PRODUCT(G29,(POWER($G$14,1))))+G29 -> 161512.13 | H30: =(PRODUCT($H$16,(POWER($H$14,1))))+H29 -> 132890
D31: Année 14 | E31: =(PRODUCT(E30,(POWER($E$14,1))))+E30 -> 1116186.4 | F31: =(PRODUCT(F30,(POWER($F$14,1))))+F30 -> 1128561 | G31: =(PRODUCT(G30,(POWER($G$14,1))))+G30 -> 167972.62 | H31: =(PRODUCT($H$16,(POWER($H$14,1))))+H30 -> 136285
D32: Année 15 | E32: =(PRODUCT(E31,(POWER(E14,1))))+E31 -> 1171995.8 | F32: =(PRODUCT(F31,(POWER($F$14,1))))+F31 -> 1184989.1 | G32: =(PRODUCT(G31,(POWER($G$14,1))))+G31 -> 174691.52 | H32: =(PRODUCT(H16,(POWER(H14,1))))+H31 -> 139680
D33: Année 16 | E33: =(PRODUCT(E32,(POWER(E14,1))))+E32 -> 1230595.5 | F33: =(PRODUCT(F32,(POWER($F$14,1))))+F32 -> 1244238.5 | G33: =(PRODUCT(G32,(POWER($G$14,1))))+G32 -> 181679.18 | H33: =(PRODUCT(H16,(POWER(H14,1))))+H32 -> 143075
D34: Durée "sur mesure" du placement 1
D35: 20 | E35: =(E16*(1-E17))*(1+E14)^D35 -> 1495796.6

Sheet Crédit
B5: =TODAY() -> 46023
E13: Somme empruntée | G13: 447072 | I13: Mensualité | K13: =-PMT(G14/12,G15,G13) -> 4399.998
E14: Taux d'intérêt de l'emprunt | G14: 0.034 | I14: Soit annuellement | K14: =K13*12 -> 52799.976
E15: Durée de l'emprunt en mois | G15: 120 | I15: Mensualité avec assurance | K15: =K13+(G13*(G16/12)) -> 4399.998
E16: Taux de l'assurance (Ci) | I16: Soit annuellement | K16: =K15*12 -> 52799.976
E17: Date début emprunt | G17: 45658 | I17: Coût total du crédit | K17: =SUM(G21:G381) -> 80927.757
I18: Coût assurance | K18: =SUM(K21:K381) -> 0
E20: Année | F20: Mois | G20: Intérets | H20: Amortissement | I20: CRD en fin de période | K20: Assurance
E21: =IF(F21<>0,G17,0) -> 45658 | F21: =IF(G15>=1,1,"") -> 1 | G21: =IFERROR(IF(F21<>"",-IPMT($G$14/12,F21,$G$15,$G$13),""),0) -> 1266.704 | H21: =IFERROR(IF(F21<>"",-PPMT($G$14/12,F21,$G$15,$G$13),""),0) -> 3133.294 | I21: =IF(F21<>"",G13-H21,"") -> 443938.71 | K21: =IF(F21<>"",$G$13*($G$16/12),"") -> 0
E22: =IFERROR(IF($G$15<=F21,"",DATE(YEAR(E21),MONTH(E21)+1,DAY(E21))),"") -> 45689 | F22: =IF(OR(F21="",F21=$G$15),"",IF(F21<$G$15,F21+1,0)) -> 2 | G22: =IFERROR(IF(F22<>"",-IPMT($G$14/12,F22,$G$15,$G$13),""),0) -> 1257.8263 | H22: =IFERROR(IF(F22<>"",-PPMT($G$14/12,F22,$G$15,$G$13),""),0) -> 3142.1716 | I22: =IF(F22<>"",I21-H22,"") -> 440796.53 | K22: =IF(F22<>"",$G$13*($G$16/12),"") -> 0
E23: =IFERROR(IF($G$15<=F22,"",DATE(YEAR(E22),MONTH(E22)+1,DAY(E22))),"") -> 45717 | F23: =IF(OR(F22="",F22=$G$15),"",IF(F22<$G$15,F22+1,0)) -> 3 | G23: =IFERROR(IF(F23<>"",-IPMT($G$14/12,F23,$G$15,$G$13),""),0) -> 1248.9235 | H23: =IFERROR(IF(F23<>"",-PPMT($G$14/12,F23,$G$15,$G$13),""),0) -> 3151.0745 | I23: =IF(F23<>"",I22-H23,"") -> 437645.46 | K23: =IF(F23<>"",$G$13*($G$16/12),"") -> 0
E24: =IFERROR(IF($G$15<=F23,"",DATE(YEAR(E23),MONTH(E23)+1,DAY(E23))),"") -> 45748 | F24: =IF(OR(F23="",F23=$G$15),"",IF(F23<$G$15,F23+1,0)) -> 4 | G24: =IFERROR(IF(F24<>"",-IPMT($G$14/12,F24,$G$15,$G$13),""),0) -> 1239.9955 | H24: =IFERROR(IF(F24<>"",-PPMT($G$14/12,F24,$G$15,$G$13),""),0) -> 3160.0025 | I24: =IF(F24<>"",I23-H24,"") -> 434485.46 | K24: =IF(F24<>"",$G$13*($G$16/12),"") -> 0
E25: =IFERROR(IF($G$15<=F24,"",DATE(YEAR(E24),MONTH(E24)+1,DAY(E24))),"") -> 45778 | F25: =IF(OR(F24="",F24=$G$15),"",IF(F24<$G$15,F24+1,0)) -> 5 | G25: =IFERROR(IF(F25<>"",-IPMT($G$14/12,F25,$G$15,$G$13),""),0) -> 1231.0421 | H25: =IFERROR(IF(F25<>"",-PPMT($G$14/12,F25,$G$15,$G$13),""),0) -> 3168.9558 | I25: =IF(F25<>"",I24-H25,"") -> 431316.5 | K25: =IF(F25<>"",$G$13*($G$16/12),"") -> 0
E26: =IFERROR(IF($G$15<=F25,"",DATE(YEAR(E25),MONTH(E25)+1,DAY(E25))),"") -> 45809 | F26: =IF(OR(F25="",F25=$G$15),"",IF(F25<$G$15,F25+1,0)) -> 6 | G26: =IFERROR(IF(F26<>"",-IPMT($G$14/12,F26,$G$15,$G$13),""),0) -> 1222.0634 | H26: =IFERROR(IF(F26<>"",-PPMT($G$14/12,F26,$G$15,$G$13),""),0) -> 3177.9346 | I26: =IF(F26<>"",I25-H26,"") -> 428138.57 | K26: =IF(F26<>"",$G$13*($G$16/12),"") -> 0
E27: =IFERROR(IF($G$15<=F26,"",DATE(YEAR(E26),MONTH(E26)+1,DAY(E26))),"") -> 45839 | F27: =IF(OR(F26="",F26=$G$15),"",IF(F26<$G$15,F26+1,0)) -> 7 | G27: =IFERROR(IF(F27<>"",-IPMT($G$14/12,F27,$G$15,$G$13),""),0) -> 1213.0593 | H27: =IFERROR(IF(F27<>"",-PPMT($G$14/12,F27,$G$15,$G$13),""),0) -> 3186.9387 | I27: =IF(F27<>"",I26-H27,"") -> 424951.63 | K27: =IF(F27<>"",$G$13*($G$16/12),"") -> 0
E28: =IFERROR(IF($G$15<=F27,"",DATE(YEAR(E27),MONTH(E27)+1,DAY(E27))),"") -> 45870 | F28: =IF(OR(F27="",F27=$G$15),"",IF(F27<$G$15,F27+1,0)) -> 8 | G28: =IFERROR(IF(F28<>"",-IPMT($G$14/12,F28,$G$15,$G$13),""),0) -> 1204.0296 | H28: =IFERROR(IF(F28<>"",-PPMT($G$14/12,F28,$G$15,$G$13),""),0) -> 3195.9684 | I28: =IF(F28<>"",I27-H28,"") -> 421755.66 | K28: =IF(F28<>"",$G$13*($G$16/12),"") -> 0
E29: =IFERROR(IF($G$15<=F28,"",DATE(YEAR(E28),MONTH(E28)+1,DAY(E28))),"") -> 45901 | F29: =IF(OR(F28="",F28=$G$15),"",IF(F28<$G$15,F28+1,0)) -> 9 | G29: =IFERROR(IF(F29<>"",-IPMT($G$14/12,F29,$G$15,$G$13),""),0) -> 1194.9744 | H29: =IFERROR(IF(F29<>"",-PPMT($G$14/12,F29,$G$15,$G$13),""),0) -> 3205.0236 | I29: =IF(F29<>"",I28-H29,"") -> 418550.64 | K29: =IF(F29<>"",$G$13*($G$16/12),"") -> 0
E30: =IFERROR(IF($G$15<=F29,"",DATE(YEAR(E29),MONTH(E29)+1,DAY(E29))),"") -> 45931 | F30: =IF(OR(F29="",F29=$G$15),"",IF(F29<$G$15,F29+1,0)) -> 10 | G30: =IFERROR(IF(F30<>"",-IPMT($G$14/12,F30,$G$15,$G$13),""),0) -> 1185.8935 | H30: =IFERROR(IF(F30<>"",-PPMT($G$14/12,F30,$G$15,$G$13),""),0) -> 3214.1045 | I30: =IF(F30<>"",I29-H30,"") -> 415336.53 | K30: =IF(F30<>"",$G$13*($G$16/12),"") -> 0
E31: =IFERROR(IF($G$15<=F30,"",DATE(YEAR(E30),MONTH(E30)+1,DAY(E30))),"") -> 45962 | F31: =IF(OR(F30="",F30=$G$15),"",IF(F30<$G$15,F30+1,0)) -> 11 | G31: =IFERROR(IF(F31<>"",-IPMT($G$14/12,F31,$G$15,$G$13),""),0) -> 1176.7868 | H31: =IFERROR(IF(F31<>"",-PPMT($G$14/12,F31,$G$15,$G$13),""),0) -> 3223.2111 | I31: =IF(F31<>"",I30-H31,"") -> 412113.32 | K31: =IF(F31<>"",$G$13*($G$16/12),"") -> 0
E32: =IFERROR(IF($G$15<=F31,"",DATE(YEAR(E31),MONTH(E31)+1,DAY(E31))),"") -> 45992 | F32: =IF(OR(F31="",F31=$G$15),"",IF(F31<$G$15,F31+1,0)) -> 12 | G32: =IFERROR(IF(F32<>"",-IPMT($G$14/12,F32,$G$15,$G$13),""),0) -> 1167.6544 | H32: =IFERROR(IF(F32<>"",-PPMT($G$14/12,F32,$G$15,$G$13),""),0) -> 3232.3436 | I32: =IF(F32<>"",I31-H32,"") -> 408880.98 | K32: =IF(F32<>"",$G$13*($G$16/12),"") -> 0
E33: =IFERROR(IF($G$15<=F32,"",DATE(YEAR(E32),MONTH(E32)+1,DAY(E32))),"") -> 46023 | F33: =IF(OR(F32="",F32=$G$15),"",IF(F32<$G$15,F32+1,0)) -> 13 | G33: =IFERROR(IF(F33<>"",-IPMT($G$14/12,F33,$G$15,$G$13),""),0) -> 1158.4961 | H33: =IFERROR(IF(F33<>"",-PPMT($G$14/12,F33,$G$15,$G$13),""),0) -> 3241.5019 | I33: =IF(F33<>"",I32-H33,"") -> 405639.48 | K33: =IF(F33<>"",$G$13*($G$16/12),"") -> 0
... E381: =IFERROR(IF($G$15<=F380,"",DATE(YEAR(E380),MONTH(E380)+1,DAY(E380))),"") | F381: =IF(OR(F380="",F380=$G$15),"",IF(F380<$G$15,F380+1,0)) | G381: =IFERROR(IF(F381<>"",-IPMT($G$14/12,F381,$G$15,$G$13),""),0) | H381: =IFERROR(IF(F381<>"",-PPMT($G$14/12,F381,$G$15,$G$13),""),0) | I381: =IF(F381<>"",I380-H381,"") | K381: =IF(F381<>"",$G$13*($G$16/12),"")

Sheet IR
B5: =TODAY() -> 46023
A7: Barème | B7: =Données!F4 -> 2026
A8: sur revenus | B8: =B7-1 -> 2025
D13: Situation familiale | G13: Marié/pacsé | J13: Estimation IR
J14: TMI… | K14: =U25 -> 0 | L14: =U26 -> 0.11 | M14: =U27 -> 0.3 | N14: =U28 -> 0.41 | O14: =U29 -> 0.45
D15: Nombre de parts | G15: =IF(G13="",0,IF(G13="Célibataire/veuf/divorcé",1,2)+(I15*0.25)) -> 2 | I15: 0 | J15: IR… | K15: =S34 -> 8830.74
D16: Isolé | J16: Montant des revenus dans cette TMI : | N16: =IF(W34<0,0,W34) -> 16370
J17: ="+CEHR" -> +CEHR | N17: =IF(IR!G13=Données!L51,IF(IR!R22<Données!N13,0,IF(IR!R22<Données!N14,(IR!R22-Données!N13)*Données!P14,((IR!R22-Données!N14)*Données!P15)+((Données!N14-Données!N13)*Données!P14))),IF(IR!R22<Données!N14,0,IF(IR!R22<Données!N15,(IR!R22-Données!N14)*Données!Q15,((IR!R22-Données!N15)*Données!Q16+((Données!N15-Données!N14)*Données!Q15))))) -> 0
H21: Déclarant 1 | K21: Déclarant 2 | T21: Estimation IR | U21: =B7 -> 2026
Q22: Revenu | R22: =IF(G13=Données!L51,IR!H35,H35+K35) -> 75000 | S22: =G15 -> 2 | T22: Situation (marié, ...) | W22: Plafond quotient
D23: Traitement et salaires | H23: 50000 | R23: =IFERROR(R22/S22,0) -> 37500 | S23: =R22/IF(T23=Données!$L$51,1,2) -> 37500 | T23: =G13 -> Marié/pacsé | W23: =IF(OR(G16="Non",G16=""),(S22-(IF(T23="Célibataire/veuf/divorcé",1,2)))*(Données!$F$18*2),IF(T23="Célibataire/veuf/divorcé",IF(S22<=2,(S22-1)*Données!$G$18,Données!$G$18+((S22-2)*Données!$F$18*2)),(S22-(IF(T23="Célibataire/veuf/divorcé",1,2)))*(Données!$F$18*2))) -> 0
D24: Revenus des associés et gérants (article 62 CGI) | R24: 1er T | S24: 2ème T | T24: Tranches | U24: TMI | V24: Retraitement | W24: IR (nb parts) | X24: IR (plaf quotient)
D25: Frais réels | H25: Non | K25: Non | R25: =IF(R23<=T25,R23,0) -> 0 | S25: =IF(S23<=T25,S23,0) -> 0 | T25: =Données!$E$13 -> 11498 | U25: =Données!$F$13 -> 0
D26: Abattement | H26: =IF(H25="Oui",I25,IF((H23+H24)<Données!$G$24,(H23+H24),IF(((H23+H24)*10%)<Données!$G$24,Données!$G$24,IF(((H23+H24)*10%)<Données!$F$24,(H23+H24)*10%,Données!$F$24)))) -> 5000 | K26: =IF(K25="Oui",L25,IF((K23+K24)<Données!$G$24,(K23+K24),IF(((K23+K24)*10%)<Données!$G$24,Données!$G$24,IF(((K23+K24)*10%)<Données!$F$24,(K23+K24)*10%,Données!$F$24)))) -> 0 | R26: =IF(AND(R23<=T26,R23>T25),R23,0) -> 0 | S26: =IF(AND(S23<=T26,S23>T25),S23,0) -> 0 | T26: =Données!$E$14 -> 29315 | U26: =Données!$F$14 -> 0.11 | V26: =T25*U26 -> 1264.78 | W26: =IF(R26>0,(R22*U26)-(V26*S22),0) -> 0 | X26: =IF(S26>0,(R22*U26)-(V26*(IF(T23="Célibataire/veuf/divorcé",1,2)))-W23,0) -> 0
D27: Pensions, retraites et rentes | K27: 20000 | R27: =IF(AND(R23<=T27,R23>T26),R23,0) -> 37500 | S27: =IF(AND(S23<=T27,S23>T26),S23,0) -> 37500 | T27: =Données!$E$15 -> 83823 | U27: =Données!$F$15 -> 0.3 | V27: =(T25-S25)*U27+(T26-T25)*(U27-U26) -> 6834.63 | W27: =IF(R27>0,(R22*U27)-(V27*S22),0) -> 8830.74 | X27: =IF(S27>0,(R22*U27)-(V27*(IF(T23="Célibataire/veuf/divorcé",1,2)))-W23,0) -> 8830.74
D28: Abattement spécial | H28: =IF((H27+K27)<Données!$G$25,(H27+K27),IF(((H27+K27)*10%)<Données!$G$25,Données!$G$25,IF(((H27+K27)*10%)<Données!$F$25,(H27+K27)*10%,Données!$F$25))) -> 2000 | R28: =IF(AND(R23<=T28,R23>T27),R23,0) -> 0 | S28: =IF(AND(S23<=T28,S23>T27),S23,0) -> 0 | T28: =Données!$E$16 -> 180294 | U28: =Données!$F$16 -> 0.41 | V28: =(T25-S25)*U28+(T26-T25)*(U28-U26)+(T27-T26)*(U28-U27) -> 16055.16 | W28: =IF(R28>0,(R22*U28)-(V28*S22),0) -> 0 | X28: =IF(S28>0,(R22*U28)-(V28*(IF(T23="Célibataire/veuf/divorcé",1,2)))-W23,0) -> 0
D29: BIC-BNC-BA imposables | R29: =IF(R23>T28,R23,0) -> 0 | S29: =IF(S23>T28,S23,0) -> 0 | T29: =Données!$E$17 -> 0 | U29: =Données!$F$17 -> 0.45 | V29: =(T25-S25)*U29+(T26-T25)*(U29-U26)+(T27-T26)*(U29-U27)+(T28-T27)*(U29-U28) -> 23266.92 | W29: =IF(R29>0,(R22*U29)-(V29*S22),0) -> 0 | X29: =IF(S29>0,(R22*U29)-(V29*(IF(T23="Célibataire/veuf/divorcé",1,2)))-W23,0) -> 0
D30: Revenus fonciers nets | H30: 12000 | W30: =SUM(W26:W29) -> 8830.74 | X30: =SUM(X26:X29) -> 8830.74
D31: Autres revenus imposables | Q31: IR avant décote | S31: =IF(W30<=X30,X30,W30) -> 8830.74 | V31: TMI | W31: =IF(W30<=X30,IF(X26>0,U26,IF(X27>0,U27,IF(X28>0,U28,IF(X29>0,U29,0)))),IF(W26>0,U26,IF(W27>0,U27,IF(W28>0,U28,IF(W29>0,U29,0))))) -> 0.3
D32: Déductions d'impôt | Q32: Décote | S32: =IF(S31=0,0,IF(AND(S31<Données!$F$19,T23="Célibataire/veuf/divorcé"),Données!$F$20-(S31*Données!$F$21),IF(AND(S31<Données!$G$19,T23="Marié/pacsé"),Données!$G$20-(S31*Données!$F$21),0))) -> 0 | U32: Reste T1 | V32: Reste T2 | W32: Seuil plaf Q | X32: Seuil décote
D33: Crédits, réductions d'impôt | Q33: IR | S33: =IF(S31-S32<0,0,S31-S32) -> 8830.74 | U33: =IF(W26>0,($R$23-$T$25)*$S$22,IF(W27>0,($R$23-T26)*$S$22,IF(W28>0,($R$23-T27)*$S$22,($R$23-T28)*$S$22))) -> 16370 | V33: =IF(X26>0,R22-(T25*IF($T$23=Données!$L$50,2,1)),IF(X27>0,R22-(T26*IF($T$23=Données!$L$50,2,1)),IF(X28>0,R22-(T27*IF($T$23=Données!$L$50,2,1)),R22-(T28*IF($T$23=Données!$L$50,2,1))))) -> 16370 | W33: =(-(V26*S22)/(U27-U26))+((W23+(IF($T$23="Célibataire/veuf/divorcé",1,2)*V27))/(U27-U26)) -> 58630 | X33: =(IF(T23=Données!$L$51,Données!$F$20,Données!$G$20)/(1+Données!$F$21)+(V26*S22))/U26 -> 32196.438
Q34: IR après réductions | S34: =S33-H33-K33 -> 8830.74 | U34: Reste dans la TMI => | W34: =IF(W31=U26,R22-X33,IF(W30>X30,U33,IF(W31=U27,R22-W33,V33))) -> 16370
D35: Revenus imposables | H35: =H23+H24-H26+H27-H28+H29+H30+H31-H32 -> 55000 | K35: =K23+K24-K26+K27+K29+K30+K31-K32 -> 20000

Sheet Impr (1)
A1: Edition étude Page 1 | W1: Titre des diapos
V2: Slide 2 | W2: OBJECTIFS & CONTEXTE | Z2: Vous souhaitez estimer le montant de votre impôt sur le revenu.
V3: Slide 3 | W3: ESTIMATION DE LA SITUATION FISCALE
C31: Etude Impôt sur le revenu
E32: Madame et Monsieur …..............
G34: =TODAY() -> 46023
C36: Prénom CGP NOM CGP
C37: Conseiller en gestion de patrimoine
A41: Edition étude Page 2
B78: =(TODAY()) -> 46023 | E78: Document non contractuel établi en fonction des dispositions fiscales ou sociales en vigueur à la date des présentes | O78: 2
A81: Edition étude Page 3
B101: Estimation de vos revenus | F101: Estimation du revenu imposable | J101: Nombre de parts fiscales | N101: TMI
B103: Déclarant 1 | C103: =IR!H23+IR!H24+IR!H27+IR!H29 -> 50000 | F103: =IR!R22 -> 75000 | J103: =IR!S22 -> 2 | N103: =IR!W31 -> 0.3
B104: Déclarant 2 | C104: =IR!K23+IR!K24+IR!K27+IR!K29 -> 20000
B110: 0 | C110: 0.11 | E110: 0.3 | H110: 0.41 | L110: 0.45
C113: =IF(N103=11%,IR!N16,"") | E113: =IF(N103=30%,IR!N16,"") -> 16370 | H113: =IF(N103=41%,IR!N16,"") | L113: =IF(N103=45%,IR!N16,"")
D116: Estimation du montant de votre impôt sur le revenu : | I116: =IR!K15 -> 8830.74
G117: + | H117: CEHR | I117: =IF(IR!G13=Données!L51,IF(IR!R22<Données!N13,0,IF(IR!R22<Données!N14,(IR!R22-Données!N13)*Données!P14,((IR!R22-Données!N14)*Données!P15)+((Données!N14-Données!N13)*Données!P14))),IF(IR!R22<Données!N14,0,IF(IR!R22<Données!N15,(IR!R22-Données!N14)*Données!Q15,((IR!R22-Données!N15)*Données!Q16+((Données!N15-Données!N14)*Données!Q15))))) -> 0
A121: Edition étude Page 4
A161: Edition étude Page suivante

Sheet Pot ER Mode
B5: =TODAY() -> 46023
D13: Vous souhaitez | J13: =IF(G13="","Faux",IF(AND(G13="Réaliser un versement N (et vérifier si le potentiel le permet)",G15=""),"Faux",IF(AND(G15="Avis IR délivré en",H15=""),"Faux","OK"))) -> Faux
D15: Documents disponibles

Sheet Avis IR N-2
B5: =TODAY() -> 46023
D12: Avis IR | L12: =IF('Pot ER Mode'!G13="Réaliser un versement N (et vérifier si le potentiel le permet)",IF('Pot ER Mode'!G15="Dernière déclaration de revenus",Données!F5,'Pot ER Mode'!H15),Données!F5) -> 2025 | M12: Sur les revenus | N12: =L12-1 -> 2024
D16: PLAFOND EPARGNE RETRAITE
D17: Le plafond disponible pour la déduction des
D18: cotisations verées en | G18: =L12 -> 2025 | H18: , pour la | S18: DIRECTION GENERALE DES FINANCES PUBLIQUES
D19: déclaration des revenus à souscrire en | I19: =G18+1 -> 2026 | J19: est de : | S19: Impôt sur les revenus de | U19: =L12-1 -> 2024
L20: Déclar. 1 | M20: Déclar. 2 | S20: Avis d'impôt établi en | U20: =L12 -> 2025
D21: Plafond total de | F21: =G18-2 -> 2023 | G21: …................................................
D23: Plafond non utilisé pour les revenus de | I23: =F21-1 -> 2022 | J23: …............
D24: Plafond non utilisé pour les revenus de | I24: =I23+1 -> 2023 | J24: …............ | K24: ="+" -> +
D25: Plafond non utilisé pour les revenus de | I25: =I24+1 -> 2024 | J25: …............ | K25: ="+" -> +
D26: Plafond calculé sur les revenus de | I26: =I25 -> 2024 | J26: …............ | K26: ="+" -> +
D28: Plafond pour les cotisations versées en | I28: =I25+1 -> 2025 | J28: …............ | K28: ="=" -> = | L28: =SUM(L23:L27) -> 0 | M28: =SUM(M23:M27) -> 0

Sheet Décla N-1
Z4: Barème | AA4: =Données!F4 -> 2026
B5: =TODAY() -> 46023 | X5: sur revenus | AA5: =AA4-1 -> 2025
Q10: Versements épargne retraite
U11: Déclarant 1 | X11: Déclarant 2
D13: Situation familiale | J13: Estimation IR | Q13: Cotisations PER 163 Quatervicies CGI
J14: TMI… | K14: =U26 -> 0 | L14: =U27 -> 0.11 | M14: =U28 -> 0.3 | N14: =U29 -> 0.41 | O14: =U30 -> 0.45 | Q14: Cotisations PERP et assimilées
D15: Nombre de parts | G15: =IF(G13="",0,IF(G13="Célibataire/veuf/divorcé",1,2)+(I15*0.25)) -> 0 | J15: IR… | K15: =S35 -> 0 | Q15: Cotisations art83 (employeur et salarié sur fiche de paie)
D16: Isolé | J16: Montant des revenus dans cette TMI : | N16: =IF(W35<0,0,W35) -> 0 | Q16: Abondement brut versé par l'employeur PERCO
J17: ="+CEHR" -> +CEHR | N17: =IF('Décla N-1'!G13=Données!L51,IF('Décla N-1'!R23<Données!N13,0,IF('Décla N-1'!R23<Données!N14,('Décla N-1'!R23-Données!N13)*Données!P14,(('Décla N-1'!R23-Données!N14)*Données!P15)+((Données!N14-Données!N13)*Données!P14))),IF('Décla N-1'!R23<Données!N14,0,IF('Décla N-1'!R23<Données!N15,('Décla N-1'!R23-Données!N14)*Données!Q15,(('Décla N-1'!R23-Données!N15)*Données!Q16+((Données!N15-Données!N14)*Données!Q15))))) -> 0 | Q17: Cotisations PER 154 bis CGI
Q18: Cotisations Madelin retraite
Q19: Cotisations prévoyance et santé Madelin (part Madelin)
U20: =IF(U19>0,"",IF(H24+H29>0,"Attention, la cotisation prévoyance entre dans le calcul du potentiel","")) | X20: =IF(G13=Données!L51,"",IF(X19>0,"",IF(K24+K29>0,"Attention, la cotisation prévoyance entre dans le calcul du potentiel","")))
H21: Déclarant 1 | K21: Déclarant 2
T22: Estimation IR | U22: =AA4 -> 2026
D23: Traitement et salaires | Q23: Revenu | R23: =IF(G13=Données!L51,'Décla N-1'!H35,H35+K35) -> 0 | S23: =G15 -> 0 | T23: Situation (marié, ...) | W23: Plafond quotient
D24: Revenus des associés et gérants (article 62 CGI) | R24: =IFERROR(R23/S23,0) -> 0 | S24: =R23/IF(T24=Données!$L$51,1,2) -> 0 | T24: =G13 -> 0 | W24: =IF(OR(G16="Non",G16=""),(S23-(IF(T24="Célibataire/veuf/divorcé",1,2)))*(Données!F18*2),IF(T24="Célibataire/veuf/divorcé",IF(S23<=2,(S23-1)*Données!G18,Données!G18+((S23-2)*Données!F18*2)),(S23-(IF(T24="Célibataire/veuf/divorcé",1,2)))*(Données!F18*2))) -> -7164
D25: Frais réels | H25: Non | K25: Non | R25: 1er T | S25: 2ème T | T25: Tranches | U25: TMI | V25: Retraitement | W25: IR (nb parts) | X25: IR (plaf quotient)
D26: Abattement | H26: =IF(H25="Oui",I25,IF((H23+H24)<Données!$G$24,(H23+H24),IF(((H23+H24)*10%)<Données!$G$24,Données!$G$24,IF(((H23+H24)*10%)<Données!$F$24,(H23+H24)*10%,Données!$F$24)))) -> 0 | K26: =IF(K25="Oui",L25,IF((K23+K24)<Données!$G$24,(K23+K24),IF(((K23+K24)*10%)<Données!$G$24,Données!$G$24,IF(((K23+K24)*10%)<Données!$F$24,(K23+K24)*10%,Données!$F$24)))) -> 0 | R26: =IF(R24<=T26,R24,0) -> 0 | S26: =IF(S24<=T26,S24,0) -> 0 | T26: =Données!E13 -> 11498 | U26: =Données!F13 -> 0
D27: Pensions, retraites et rentes | R27: =IF(AND(R24<=T27,R24>T26),R24,0) -> 0 | S27: =IF(AND(S24<=T27,S24>T26),S24,0) -> 0 | T27: =Données!E14 -> 29315 | U27: =Données!F14 -> 0.11 | V27: =T26*U27 -> 1264.78 | W27: =IF(R27>0,(R23*U27)-(V27*S23),0) -> 0 | X27: =IF(S27>0,(R23*U27)-(V27*(IF(T24="Célibataire/veuf/divorcé",1,2)))-W24,0) -> 0
D28: Abattement spécial | H28: =IF((H27+K27)<Données!$G$25,(H27+K27),IF(((H27+K27)*10%)<Données!$G$25,Données!$G$25,IF(((H27+K27)*10%)<Données!$F$25,(H27+K27)*10%,Données!$F$25))) -> 0 | R28: =IF(AND(R24<=T28,R24>T27),R24,0) -> 0 | S28: =IF(AND(S24<=T28,S24>T27),S24,0) -> 0 | T28: =Données!E15 -> 83823 | U28: =Données!F15 -> 0.3 | V28: =(T26-S26)*U28+(T27-T26)*(U28-U27) -> 6834.63 | W28: =IF(R28>0,(R23*U28)-(V28*S23),0) -> 0 | X28: =IF(S28>0,(R23*U28)-(V28*(IF(T24="Célibataire/veuf/divorcé",1,2)))-W24,0) -> 0
D29: BIC-BNC-BA imposables | R29: =IF(AND(R24<=T29,R24>T28),R24,0) -> 0 | S29: =IF(AND(S24<=T29,S24>T28),S24,0) -> 0 | T29: =Données!E16 -> 180294 | U29: =Données!F16 -> 0.41 | V29: =(T26-S26)*U29+(T27-T26)*(U29-U27)+(T28-T27)*(U29-U28) -> 16055.16 | W29: =IF(R29>0,(R23*U29)-(V29*S23),0) -> 0 | X29: =IF(S29>0,(R23*U29)-(V29*(IF(T24="Célibataire/veuf/divorcé",1,2)))-W24,0) -> 0
D30: Revenus fonciers nets | R30: =IF(R24>T29,R24,0) -> 0 | S30: =IF(S24>T29,S24,0) -> 0 | T30: =Données!E17 -> 0 | U30: =Données!F17 -> 0.45 | V30: =(T26-S26)*U30+(T27-T26)*(U30-U27)+(T28-T27)*(U30-U28)+(T29-T28)*(U30-U29) -> 23266.92 | W30: =IF(R30>0,(R23*U30)-(V30*S23),0) -> 0 | X30: =IF(S30>0,(R23*U30)-(V30*(IF(T24="Célibataire/veuf/divorcé",1,2)))-W24,0) -> 0
D31: Autres revenus imposables | W31: =SUM(W27:W30) -> 0 | X31: =SUM(X27:X30) -> 0
D32: Déductions d'impôt (autres que PER) | Q32: IR avant décote | S32: =IF(W31<=X31,X31,W31) -> 0 | V32: TMI | W32: =IF(W31<=X31,IF(X27>0,U27,IF(X28>0,U28,IF(X29>0,U29,IF(X30>0,U30,0)))),IF(W27>0,U27,IF(W28>0,U28,IF(W29>0,U29,IF(W30>0,U30,0))))) -> 0
D33: Crédits, réductions d'impôt | Q33: Décote | S33: =IF(S32=0,0,IF(AND(S32<Données!$F$19,T24="Célibataire/veuf/divorcé"),Données!$F$20-(S32*Données!$F$21),IF(AND(S32<Données!$G$19,T24="Marié/pacsé"),Données!$G$20-(S32*Données!$F$21),0))) -> 0 | U33: Reste T1 | V33: Reste T2 | W33: Seuil plaf Q | X33: Seuil décote
Q34: IR | S34: =IF(S32-S33<0,0,S32-S33) -> 0 | U34: =IF(W27>0,($R$24-$T$26)*$S$23,IF(W28>0,($R$24-T27)*$S$23,IF(W29>0,($R$24-T28)*$S$23,($R$24-T29)*$S$23))) -> 0 | V34: =IF(X27>0,R23-(T26*IF($T$24=Données!$L$50,2,1)),IF(X28>0,R23-(T27*IF($T$24=Données!$L$50,2,1)),IF(X29>0,R23-(T28*IF($T$24=Données!$L$50,2,1)),R23-(T29*IF($T$24=Données!$L$50,2,1))))) -> -180294 | W34: =(-(V27*S23)/(U28-U27))+((W24+(IF($T$24="Célibataire/veuf/divorcé",1,2)*V28))/(U28-U27)) -> 34238.211 | X34: =(IF(T24=Données!$L$51,Données!$F$20,Données!$G$20)/(1+Données!$F$21)+(V27*S23))/U27 -> 9200.4381
D35: Revenus imposables | H35: =H23+H24-H26+H27-H28+H29+H30+H31-H32-'Synthèse décla'!I34 -> 0 | K35: =K23+K24-K26+K27+K29+K30+K31-K32-'Synthèse décla'!J34 -> 0 | Q35: IR après réductions | S35: =S34-H33-K33 -> 0 | U35: Reste dans la TMI => | W35: =IF(W32=U27,R23-X34,IF(W31>X31,U34,IF(W32=U28,R23-W34,V34))) -> -180294

Sheet Synthèse décla
Q4: Barème | R4: =Données!F4 -> 2026
B5: =TODAY() -> 46023 | Q5: sur revenus | R5: =R4-1 -> 2025
Q9: PASS | R9: =J13 -> 2025
Q10: =VLOOKUP(J13,Données!$D$50:$E$56,2) -> 47100
D13: Déclatation des revenus | G13: =R4 -> 2026 | H13: Sur les revenus | J13: =G13-1 -> 2025 | N13: Choix pour le report 154 bis (Madelin) : | O13: Interprétation recalcul sur Revenu Brut Global
M14: Mad 15 décla1 | N14: =IF(O14-Q10<=0,0,IF(O14<='Synthèse décla'!$Q$10,0,IF(O14<=8*'Synthèse décla'!$Q$10,(O14-'Synthèse décla'!$Q$10)*0.15,((8*'Synthèse décla'!$Q$10)-'Synthèse décla'!$Q$10)*0.15))) -> 0 | O14: =IF('Décla N-1'!H24-'Décla N-1'!H26+'Décla N-1'!H29<0,0,'Décla N-1'!H24-'Décla N-1'!H26+'Décla N-1'!H29) -> 0 | P14: =IF('Décla N-1'!K24-'Décla N-1'!K26+'Décla N-1'!K29<0,0,'Décla N-1'!K24-'Décla N-1'!K26+'Décla N-1'!K29) -> 0 | Q14: =IF(P14-Q10<=0,0,IF(P14<='Synthèse décla'!$Q$10,0,IF(P14<=8*'Synthèse décla'!$Q$10,(P14-'Synthèse décla'!$Q$10)*0.15,((8*'Synthèse décla'!$Q$10)-'Synthèse décla'!$Q$10)*0.15))) -> 0 | R14: Mad 15 Décla2
D15: Epargne retraite (2042) | H15: Déclarant 1 | J15: Déclarant 2 | M15: Déclarant 1 : Potentiel 154 BIS (Madelin retraite) | P15: Déclarant 2 : Potentiel 154 BIS (Madelin retraite)
D16: Cotisations versées sur les nouveaux plans d'épargne retraite (PER) déduction du revenu global…….............6NS | H16: ='Décla N-1'!U13 -> 0 | I16: 6NT | J16: ='Décla N-1'!X13 -> 0 | M16: Revenu imposable TNS | N16: ='Décla N-1'!H24+'Décla N-1'!H29 -> 0 | P16: Revenu imposable TNS | Q16: ='Décla N-1'!K24+'Décla N-1'!K29 -> 0
D17: Cotisations PERP, Préfon, Corem, CGOS et assimilées…................................................................................6RS | H17: ='Décla N-1'!U14 -> 0 | I17: 6RT | J17: ='Décla N-1'!X14 -> 0 | M17: Assiette Madelin | N17: =N16+N18+N19+'Décla N-1'!U19 -> 0 | P17: Assiette Madelin | Q17: =Q16+Q18+Q19+'Décla N-1'!X19 -> 0
D18: Plafond de déduction…..............................................................................................................................6PS | I18: 6PT | M18: Versement Madelin retraite | N18: ='Décla N-1'!U18 -> 0 | P18: Versement Madelin Retraite | Q18: ='Décla N-1'!$X$18 -> 0
D19: Vous souhaitez bénéficier du plafond de votre conjoint…..................................................................................... | H19: ............................ | I19: .…..................6QR | J19: Non | L19: =IF('Décla N-1'!G13=Données!L51,"",IF(J19="Oui","",IF(OR(J17+J16>J34,H16+H17>I34),"?",""))) | M19: Versement PER 154bis | N19: ='Décla N-1'!U17 -> 0 | P19: Versement PER 154bis | Q19: ='Décla N-1'!$X$17 -> 0
D20: Vous êtes nouvellement domicilié en France en…................................................................................................. | H20: ............................ | I20: ….................6QW | M20: Potentiel Madelin total | N20: =N21+N22 -> 0 | P20: Potentiel Madelin total | Q20: =Q21+Q22 -> 0
D21: Cotisations sur les nouveaux plans d'épargne retraite déduites des BIC, BNC, BA, Rem art62….....................6OS | H21: =IF(O13="Interprétation recalcul sur Revenu Brut Global",MAX(0,IF(IF(N18<N14,0,N18-N14)>0,N19,(N19+N18)-N14)),MAX(0,IF(IF(N18<N21,0,N18-N21)>0,N19,(N19+N18)-N21))) -> 0 | I21: 6OT | J21: =IF(O13="Interprétation recalcul sur Revenu Brut Global",MAX(0,IF(IF(Q18<Q14,0,Q18-Q14)>0,Q19,(Q19+Q18)-Q14)),MAX(0,IF(IF(Q18<Q21,0,Q18-Q21)>0,Q19,(Q19+Q18)-Q21))) -> 0 | M21: Enveloppe 15% | N21: =IF(N17<='Synthèse décla'!$Q$10,0,IF(N17<=8*'Synthèse décla'!$Q$10,(N17-'Synthèse décla'!$Q$10)*0.15,((8*'Synthèse décla'!$Q$10)-'Synthèse décla'!$Q$10)*0.15)) -> 0 | O21: =IF((N18+N19)>=N21,0,N21-(N18+N19)) -> 0 | P21: Enveloppe 15% | Q21: =IF(Q17<='Synthèse décla'!$Q$10,0,IF(Q17<=8*'Synthèse décla'!$Q$10,(Q17-'Synthèse décla'!$Q$10)*0.15,((8*'Synthèse décla'!$Q$10)-'Synthèse décla'!$Q$10)*0.15)) -> 0 | R21: =IF((Q18+Q19)>=Q21,0,Q21-(Q18+Q19)) -> 0
D22: Autres cotisations déduites des BIC, BNC, BA, rémun. art. 62 ou salaires …..................................................6QS | H22: =IF(O13="Interprétation recalcul sur Revenu Brut Global",'Décla N-1'!U16+'Décla N-1'!U15+IF(N18<N14,0,N18-N14),'Décla N-1'!U16+'Décla N-1'!U15+IF(N18<N21,0,N18-N21)) -> 0 | I22: 6QT | J22: =IF(O13="Interprétation recalcul sur Revenu Brut Global",'Décla N-1'!X16+'Décla N-1'!X15+IF(Q18<Q14,0,Q18-Q14),'Décla N-1'!X16+'Décla N-1'!X15+IF(Q18<Q21,0,Q18-Q21)) -> 0 | M22: Enveloppe 10% | N22: =IF(N16=0,0,IF(N17<='Synthèse décla'!$Q$10,0.1*'Synthèse décla'!$Q$10,IF(N17<=8*'Synthèse décla'!$Q$10,N17*0.1,8*'Synthèse décla'!$Q$10*0.1))) -> 0 | O22: =IF(N16=0,0,IF(('Décla N-1'!U15+'Décla N-1'!U16)>=N22,IF((N18+N19)>N21,N22-(MAX(0,IF(IF(N18<N21,0,N18-N21)>0,N19,(N19+N18)-N21)))-('Décla N-1'!U16+'Décla N-1'!U15+IF(N18<N21,0,N18-N21)),0),N22-(MAX(0,IF(IF(N18<N21,0,N18-N21)>0,N19,(N19+N18)-N21)))-('Décla N-1'!U16+'Décla N-1'!U15+IF(N18<N21,0,N18-N21)))) -> 0 | P22: Enveloppe 10% | Q22: =IF(Q16=0,0,IF(Q17<='Synthèse décla'!$Q$10,0.1*'Synthèse décla'!$Q$10,IF(Q17<=8*'Synthèse décla'!$Q$10,Q17*0.1,8*'Synthèse décla'!$Q$10*0.1))) -> 0 | R22: =IF(Q16=0,0,IF(('Décla N-1'!X15+'Décla N-1'!X16)>=Q22,IF((Q18+Q19)>Q21,Q22-(MAX(0,IF(IF(Q18<Q21,0,Q18-Q21)>0,Q19,(Q19+Q18)-Q21)))-('Décla N-1'!X16+'Décla N-1'!X15+IF(Q18<Q21,0,Q18-Q21)),0),Q22-(MAX(0,IF(IF(Q18<Q21,0,Q18-Q21)>0,Q19,(Q19+Q18)-Q21)))-('Décla N-1'!X16+'Décla N-1'!X15+IF(Q18<Q21,0,Q18-Q21)))) -> 0
M23: Potentiel Madelin restant : | O23: =O21+O22 -> 0 | P23: Potentiel Madelin restant | R23: =R21+R22 -> 0
M24: =IF(O23<0,"Réintégration fiscale à opérer","") | P24: =IF('Décla N-1'!G13=Données!L51,"",IF(R23<0,"Réintégration fiscale à opérer",""))
D25: Simulation de l'AVIS IR
D27: AVIS D'IMPÔT | F27: =G13 -> 2026
D28: PLAFOND EPARGNE RETRAITE | H28: total cotiz | I28: =H16+H17 -> 0 | J28: =J16+J17 -> 0 | N28: report en avant déclarant 1 | Q28: Données pour calcul 2023
D29: Le plafond disponible pour la déduction des cotisations verées en …........ | G29: =F27 -> 2026 | H29: total plaf | I29: =I32+J32 -> 0 | M29: ='Avis IR N-2'!L23 -> 0 | N29: =IF(N32=0,0,IF(N32<=M29,0,N32-M29)) -> 0 | O29: =M29-N32 -> 0 | Q29: Déclarant 1 | R29: Déclarant 2
D30: pour la déclaration des revenus à souscrire en …...................................... | G30: =G29+1 -> 2027 | I30: =I32-H16-H17 -> 0 | J30: =J32-J16-J17 -> 0 | M30: ='Avis IR N-2'!L24 -> 0 | N30: =IF(N29=0,0,IF(N29<=M30,0,N29-M30)) -> 0 | O30: =M30-N29 -> 0 | Q30: ='Décla N-1'!H23+'Décla N-1'!H24-'Décla N-1'!H26+'Décla N-1'!H29 -> 0 | R30: ='Décla N-1'!K23+'Décla N-1'!K24-'Décla N-1'!K26+'Décla N-1'!K29 -> 0
I31: Déclar. 1 | J31: Déclar. 2 | M31: ='Avis IR N-2'!L25 -> 0 | N31: =IF(N30=0,0,IF(N30<=M31,0,N30-M31)) -> 0 | O31: =M31-N30 -> 0
D32: Plafond total de …...................................................................................... | G32: =G29-2 -> 2024 | I32: ='Avis IR N-2'!L28 -> 0 | J32: =IF('Décla N-1'!G13=Données!L51,0,'Avis IR N-2'!M28) -> 0 | M32: ='Avis IR N-2'!L26 -> 0 | N32: =IF(I34<=M32,IF(OR(J19="Non",J19=""),0,IF(J34>J32,I34+J34-J32-M32,I34-M32)),IF(J19="Non",I34-M32,IF(J34>J32,I34+J34-J32-M32,I34-M32))) -> 0 | O32: =M32-IF(OR(J19="Non",J19=""),I34,J33-J32+I34) -> 0 | Q32: PASS
D33: Plafond après mutualisation…................................................................... | I33: =IF(AND(I28>=I32,J19="Oui",J30>=0),I32+IF(J30>=(I28-I32),I28-I32,J30),IF(J19="Oui",IF(J28>J32,IF(I30+J30>0,I29-J28,I28),I32),"")) | J33: =IF(AND(J28>=J32,J19="Oui",I30>=0),J32+IF(I30>=(J28-J32),J28-J32,I30),IF(J19="Oui",IF(I28>I32,IF(J30+I30>0,I29-I28,J28),J32),"")) | Q33: =Données!D50 -> 2019 | R33: =Données!E50 -> 40524
D34: Cotisations prises en compte pour …......................................................... | G34: =G32+1 -> 2025 | I34: =IF((H16+H17)>I32,IF(J19="Oui",I33,I32),(H16+H17)) -> 0 | J34: =IF('Décla N-1'!G13=Données!L51,0,IF((J16+J17)>J32,IF(J19="Oui",J33,J32),(J16+J17))) -> 0 | N34: report en avant déclarant 2 | Q34: =Données!D51 -> 2020 | R34: =Données!E51 -> 41136
D35: Plafond non utilisé pour les revenus de ….................................................. | G35: =G32-1 -> 2023 | I35: =IF(O30>0,O30,0) -> 0 | J35: =IF('Décla N-1'!G13=Données!L51,0,IF(O36>0,O36,0)) -> 0 | M35: ='Avis IR N-2'!M23 -> 0 | N35: =IF(N38=0,0,IF(N38<=M35,0,N38-M35)) -> 0 | O35: =M35-N38 -> 0 | Q35: =Données!D52 -> 2021 | R35: =Données!E52 -> 41136
D36: Plafond non utilisé pour les revenus de ….................................................. | G36: =G35+1 -> 2024 | H36: ="+" -> + | I36: =IF(O31>0,O31,0) -> 0 | J36: =IF('Décla N-1'!G13=Données!L51,0,IF(O37>0,O37,0)) -> 0 | M36: ='Avis IR N-2'!M24 -> 0 | N36: =IF(N35=0,0,IF(N35<=M36,0,N35-M36)) -> 0 | O36: =M36-N35 -> 0 | Q36: =Données!D53 -> 2022 | R36: =Données!E53 -> 41136
D37: Plafond non utilisé pour les revenus de ….................................................. | G37: =G36+1 -> 2025 | H37: ="+" -> + | I37: =IF(O32>0,O32,0) -> 0 | J37: =IF('Décla N-1'!G13=Données!L51,0,IF(O38>0,O38,0)) -> 0 | M37: ='Avis IR N-2'!M25 -> 0 | N37: =IF(N36=0,0,IF(N36<=M37,0,N36-M37)) -> 0 | O37: =M37-N36 -> 0 | Q37: =Données!D54 -> 2023 | R37: =Données!E54 -> 43992
D38: Plafond calculé sur les revenus de ….......................................................... | G38: =G37 -> 2025 | H38: ="+" -> + | I38: =IF(Q30<=(INDEX($Q$33:$R$39,MATCH($G$38,$Q$33:$Q$39,0),2)),INDEX($Q$33:$R$39,MATCH($G$38,$Q$33:$Q$39,0),2)*10%,IF(Q30>(8*(INDEX($Q$33:$R$39,MATCH($G$38,$Q$33:$Q$39,0),2))),(8*(INDEX($Q$33:$R$39,MATCH($G$38,$Q$33:$Q$39,0),2)))*10%,Q30*10%))-IF(IF(Q30<=(INDEX($Q$33:$R$39,MATCH($G$38,$Q$33:$Q$39,0),2)),INDEX($Q$33:$R$39,MATCH($G$38,$Q$33:$Q$39,0),2)*10%,IF(Q30>(8*(INDEX($Q$33:$R$39,MATCH($G$38,$Q$33:$Q$39,0),2))),(8*(INDEX($Q$33:$R$39,MATCH($G$38,$Q$33:$Q$39,0),2)))*10%,Q30*10%))>(H21+H22),(H21+H22),IF(Q30<=(INDEX($Q$33:$R$39,MATCH($G$38,$Q$33:$Q$39,0),2)),INDEX($Q$33:$R$39,MATCH($G$38,$Q$33:$Q$39,0),2)*10%,IF(Q30>(8*(INDEX($Q$33:$R$39,MATCH($G$38,$Q$33:$Q$39,0),2))),(8*(INDEX($Q$33:$R$39,MATCH($G$38,$Q$33:$Q$39,0),2)))*10%,Q30*10%))) -> 4710 | J38: =IF('Décla N-1'!G13=Données!L51,0,IF(R30<=(INDEX($Q$33:$R$39,MATCH($G$38,$Q$33:$Q$39,0),2)),INDEX($Q$33:$R$39,MATCH($G$38,$Q$33:$Q$39,0),2)*10%,IF(R30>(8*(INDEX($Q$33:$R$39,MATCH($G$38,$Q$33:$Q$39,0),2))),(8*(INDEX($Q$33:$R$39,MATCH($G$38,$Q$33:$Q$39,0),2)))*10%,R30*10%))-IF(IF(R30<=(INDEX($Q$33:$R$39,MATCH($G$38,$Q$33:$Q$39,0),2)),INDEX($Q$33:$R$39,MATCH($G$38,$Q$33:$Q$39,0),2)*10%,IF(R30>(8*(INDEX($Q$33:$R$39,MATCH($G$38,$Q$33:$Q$39,0),2))),(8*(INDEX($Q$33:$R$39,MATCH($G$38,$Q$33:$Q$39,0),2)))*10%,R30*10%))>(J21+J22),(J21+J22),IF(R30<=(INDEX($Q$33:$R$39,MATCH($G$38,$Q$33:$Q$39,0),2)),INDEX($Q$33:$R$39,MATCH($G$38,$Q$33:$Q$39,0),2)*10%,IF(R30>(8*(INDEX($Q$33:$R$39,MATCH($G$38,$Q$33:$Q$39,0),2))),(8*(INDEX($Q$33:$R$39,MATCH($G$38,$Q$33:$Q$39,0),2)))*10%,R30*10%)))) -> 4710 | M38: ='Avis IR N-2'!M26 -> 0 | N38: =IF(J34<=M38,IF(OR(J19="Non",J19=""),0,IF(I34>I32,I34+J34-I32-M38,J34-M38)),IF(P15="Non",J34-M38,IF(I34>I32,I34+J34-I32-M38,J34-M38))) -> 0 | O38: =M38-IF(OR(J19="Non",J19=""),J34,I33-I32+J34) -> 0 | Q38: =Données!D55 -> 2024 | R38: =Données!E55 -> 46368
D39: Plafond pour les cotisations versées en ….................................................. | G39: =G37+1 -> 2026 | H39: ="=" -> = | I39: =SUM(I35:I38) -> 4710 | J39: =IF('Décla N-1'!G13=Données!L51,0,SUM(J35:J38)) -> 4710 | Q39: =Données!D56 -> 2025 | R39: =Données!E56 -> 47100

Sheet Estimation N
Z4: Barème | AA4: =Données!F4 -> 2026
B5: =TODAY() -> 46023 | X5: sur revenus | AA5: =AA4-1 -> 2025
Q10: Versements épargne retraite
U11: Déclarant 1 | X11: Déclarant 2
D13: Situation familiale | J13: Estimation IR | Q13: Cotisations PER 163 Quatervicies CGI
J14: TMI… | K14: =U26 -> 0 | L14: =U27 -> 0.11 | M14: =U28 -> 0.3 | N14: =U29 -> 0.41 | O14: =U30 -> 0.45 | Q14: Cotisations PERP et assimilées
D15: Nombre de parts | G15: =IF(G13="",0,IF(G13="Célibataire/veuf/divorcé",1,2)+(I15*0.25)) -> 0 | J15: IR… | K15: =S35 -> 0 | Q15: Cotisations art83 (employeur et salarié sur fiche de paie)
D16: Isolé | J16: Montant des revenus dans cette TMI : | N16: =IF(W35<0,0,W35) -> 0 | Q16: Abondement brut versé par l'employeur PERCO
J17: ="+CEHR" -> +CEHR | N17: =IF('Estimation N'!G13=Données!L51,IF('Estimation N'!R23<Données!N13,0,IF('Estimation N'!R23<Données!N14,('Estimation N'!R23-Données!N13)*Données!P14,(('Estimation N'!R23-Données!N14)*Données!P15)+((Données!N14-Données!N13)*Données!P14))),IF('Estimation N'!R23<Données!N14,0,IF('Estimation N'!R23<Données!N15,('Estimation N'!R23-Données!N14)*Données!Q15,(('Estimation N'!R23-Données!N15)*Données!Q16+((Données!N15-Données!N14)*Données!Q15))))) -> 0 | Q17: Cotisations PER 154 bis CGI
Q18: Cotisations Madelin retraite
Q19: Cotisations prévoyance et santé Madelin (part Madelin)
U20: =IF(U19>0,"",IF(H24+H29>0,"Attention, la cotisation prévoyance entre dans le calcul du potentiel","")) | X20: =IF(G13=Données!L51,"",IF(X19>0,"",IF(K24+K29>0,"Attention, la cotisation prévoyance entre dans le calcul du potentiel","")))
H21: Déclarant 1 | K21: Déclarant 2
T22: Estimation IR | U22: =AA4 -> 2026
D23: Traitement et salaires | Q23: Revenu | R23: =IF(G13=Données!L51,'Estimation N'!H35,H35+K35) -> 0 | S23: =G15 -> 0 | T23: Situation (marié, ...) | W23: Plafond quotient
D24: Revenus des associés et gérants (article 62 CGI) | R24: =IFERROR(R23/S23,0) -> 0 | S24: =R23/IF(T24=Données!$L$51,1,2) -> 0 | T24: =G13 -> 0 | W24: =IF(OR(G16="Non",G16=""),(S23-(IF(T24="Célibataire/veuf/divorcé",1,2)))*(Données!F18*2),IF(T24="Célibataire/veuf/divorcé",IF(S23<=2,(S23-1)*Données!G18,Données!G18+((S23-2)*Données!F18*2)),(S23-(IF(T24="Célibataire/veuf/divorcé",1,2)))*(Données!F18*2))) -> -7164
D25: Frais réels | H25: Non | K25: Non | R25: 1er T | S25: 2ème T | T25: Tranches | U25: TMI | V25: Retraitement | W25: IR (nb parts) | X25: IR (plaf quotient)
D26: Abattement | H26: =IF(H25="Oui",I25,IF((H23+H24)<Données!$G$24,(H23+H24),IF(((H23+H24)*10%)<Données!$G$24,Données!$G$24,IF(((H23+H24)*10%)<Données!$F$24,(H23+H24)*10%,Données!$F$24)))) -> 0 | K26: =IF(K25="Oui",L25,IF((K23+K24)<Données!$G$24,(K23+K24),IF(((K23+K24)*10%)<Données!$G$24,Données!$G$24,IF(((K23+K24)*10%)<Données!$F$24,(K23+K24)*10%,Données!$F$24)))) -> 0 | R26: =IF(R24<=T26,R24,0) -> 0 | S26: =IF(S24<=T26,S24,0) -> 0 | T26: =Données!E13 -> 11498 | U26: =Données!F13 -> 0
D27: Pensions, retraites et rentes | R27: =IF(AND(R24<=T27,R24>T26),R24,0) -> 0 | S27: =IF(AND(S24<=T27,S24>T26),S24,0) -> 0 | T27: =Données!E14 -> 29315 | U27: =Données!F14 -> 0.11 | V27: =T26*U27 -> 1264.78 | W27: =IF(R27>0,(R23*U27)-(V27*S23),0) -> 0 | X27: =IF(S27>0,(R23*U27)-(V27*(IF(T24="Célibataire/veuf/divorcé",1,2)))-W24,0) -> 0
D28: Abattement spécial | H28: =IF((H27+K27)<Données!$G$25,(H27+K27),IF(((H27+K27)*10%)<Données!$G$25,Données!$G$25,IF(((H27+K27)*10%)<Données!$F$25,(H27+K27)*10%,Données!$F$25))) -> 0 | R28: =IF(AND(R24<=T28,R24>T27),R24,0) -> 0 | S28: =IF(AND(S24<=T28,S24>T27),S24,0) -> 0 | T28: =Données!E15 -> 83823 | U28: =Données!F15 -> 0.3 | V28: =(T26-S26)*U28+(T27-T26)*(U28-U27) -> 6834.63 | W28: =IF(R28>0,(R23*U28)-(V28*S23),0) -> 0 | X28: =IF(S28>0,(R23*U28)-(V28*(IF(T24="Célibataire/veuf/divorcé",1,2)))-W24,0) -> 0
D29: BIC-BNC-BA imposables | R29: =IF(AND(R24<=T29,R24>T28),R24,0) -> 0 | S29: =IF(AND(S24<=T29,S24>T28),S24,0) -> 0 | T29: =Données!E16 -> 180294 | U29: =Données!F16 -> 0.41 | V29: =(T26-S26)*U29+(T27-T26)*(U29-U27)+(T28-T27)*(U29-U28) -> 16055.16 | W29: =IF(R29>0,(R23*U29)-(V29*S23),0) -> 0 | X29: =IF(S29>0,(R23*U29)-(V29*(IF(T24="Célibataire/veuf/divorcé",1,2)))-W24,0) -> 0
D30: Revenus fonciers nets | R30: =IF(R24>T29,R24,0) -> 0 | S30: =IF(S24>T29,S24,0) -> 0 | T30: =Données!E17 -> 0 | U30: =Données!F17 -> 0.45 | V30: =(T26-S26)*U30+(T27-T26)*(U30-U27)+(T28-T27)*(U30-U28)+(T29-T28)*(U30-U29) -> 23266.92 | W30: =IF(R30>0,(R23*U30)-(V30*S23),0) -> 0 | X30: =IF(S30>0,(R23*U30)-(V30*(IF(T24="Célibataire/veuf/divorcé",1,2)))-W24,0) -> 0
D31: Autres revenus imposables | W31: =SUM(W27:W30) -> 0 | X31: =SUM(X27:X30) -> 0
D32: Déductions d'impôt (autres que PER) | Q32: IR avant décote | S32: =IF(W31<=X31,X31,W31) -> 0 | V32: TMI | W32: =IF(W31<=X31,IF(X27>0,U27,IF(X28>0,U28,IF(X29>0,U29,IF(X30>0,U30,0)))),IF(W27>0,U27,IF(W28>0,U28,IF(W29>0,U29,IF(W30>0,U30,0))))) -> 0
D33: Crédits, réductions d'impôt | Q33: Décote | S33: =IF(S32=0,0,IF(AND(S32<Données!$F$19,T24="Célibataire/veuf/divorcé"),Données!$F$20-(S32*Données!$F$21),IF(AND(S32<Données!$G$19,T24="Marié/pacsé"),Données!$G$20-(S32*Données!$F$21),0))) -> 0 | U33: Reste T1 | V33: Reste T2 | W33: Seuil plaf Q | X33: Seuil décote
Q34: IR | S34: =IF(S32-S33<0,0,S32-S33) -> 0 | U34: =IF(W27>0,($R$24-$T$26)*$S$23,IF(W28>0,($R$24-T27)*$S$23,IF(W29>0,($R$24-T28)*$S$23,($R$24-T29)*$S$23))) -> 0 | V34: =IF(X27>0,R23-(T26*IF($T$24=Données!$L$50,2,1)),IF(X28>0,R23-(T27*IF($T$24=Données!$L$50,2,1)),IF(X29>0,R23-(T28*IF($T$24=Données!$L$50,2,1)),R23-(T29*IF($T$24=Données!$L$50,2,1))))) -> -180294 | W34: =(-(V27*S23)/(U28-U27))+((W24+(IF($T$24="Célibataire/veuf/divorcé",1,2)*V28))/(U28-U27)) -> 34238.211 | X34: =(IF(T24=Données!$L$51,Données!$F$20,Données!$G$20)/(1+Données!$F$21)+(V27*S23))/U27 -> 9200.4381
D35: Revenus imposables | H35: =H23+H24-H26+H27-H28+H29+H30+H31-H32-Synthèse!I34 -> 0 | K35: =K23+K24-K26+K27+K29+K30+K31-K32-Synthèse!J34 -> 0 | Q35: IR après réductions | S35: =S34-H33-K33 -> 0 | U35: Reste dans la TMI => | W35: =IF(W32=U27,R23-X34,IF(W31>X31,U34,IF(W32=U28,R23-W34,V34))) -> -180294

Sheet Synthèse
Q4: Barème | R4: =Données!F4 -> 2026
B5: =TODAY() -> 46023 | Q5: sur revenus | R5: =R4-1 -> 2025
Q9: PASS | R9: =J13 -> 2026
Q10: =VLOOKUP(J13,Données!$D$50:$E$56,2) -> 47100
D13: Déclatation des revenus | G13: =R4+1 -> 2027 | H13: Sur les revenus | J13: =G13-1 -> 2026 | N13: Choix pour le report 154 bis (Madelin) : | O13: Interprétation recalcul sur Revenu Brut Global
M14: Mad 15 décla1 | N14: =IF(O14-Q10<=0,0,IF(O14<=Synthèse!$Q$10,0,IF(O14<=8*Synthèse!$Q$10,(O14-Synthèse!$Q$10)*0.15,((8*Synthèse!$Q$10)-Synthèse!$Q$10)*0.15))) -> 0 | O14: =IF('Estimation N'!H24-'Estimation N'!H26+'Estimation N'!H29<0,0,'Estimation N'!H24-'Estimation N'!H26+'Estimation N'!H29) -> 0 | P14: =IF('Estimation N'!K24-'Estimation N'!K26+'Estimation N'!K29<0,0,'Estimation N'!K24-'Estimation N'!K26+'Estimation N'!K29) -> 0 | Q14: =IF(P14-Q10<=0,0,IF(P14<=Synthèse!$Q$10,0,IF(P14<=8*Synthèse!$Q$10,(P14-Synthèse!$Q$10)*0.15,((8*Synthèse!$Q$10)-Synthèse!$Q$10)*0.15))) -> 0 | R14: Mad 15 Décla2
D15: Epargne retraite (2042) | H15: Déclarant 1 | J15: Déclarant 2 | M15: Déclarant 1 : Potentiel 154 BIS (Madelin retraite) | P15: Déclarant 2 : Potentiel 154 BIS (Madelin retraite)
D16: Cotisations versées sur les nouveaux plans d'épargne retraite (PER) déduction du revenu global…….............6NS | H16: ='Estimation N'!U13 -> 0 | I16: 6NT | J16: ='Estimation N'!X13 -> 0 | M16: Revenu imposable TNS | N16: ='Estimation N'!H24+'Estimation N'!H29 -> 0 | P16: Revenu imposable TNS | Q16: ='Estimation N'!K24+'Estimation N'!K29 -> 0
D17: Cotisations PERP, Préfon, Corem, CGOS et assimilées…................................................................................6RS | H17: ='Estimation N'!U14 -> 0 | I17: 6RT | J17: ='Estimation N'!X14 -> 0 | M17: Assiette Madelin | N17: =N16+N18+N19+'Estimation N'!U19 -> 0 | P17: Assiette Madelin | Q17: =Q16+Q18+Q19+'Estimation N'!X19 -> 0
D18: Plafond de déduction…..............................................................................................................................6PS | I18: 6PT | M18: Versement Madelin retraite | N18: ='Estimation N'!U18 -> 0 | P18: Versement Madelin Retraite | Q18: ='Estimation N'!$X$18 -> 0
D19: Vous souhaitez bénéficier du plafond de votre conjoint…..................................................................................... | H19: ............................ | I19: .…..................6QR | J19: Non | L19: =IF('Estimation N'!G13=Données!L51,"",IF(J19="Oui","",IF(OR(J17+J16>J34,H16+H17>I34),"?",""))) | M19: Versement PER 154bis | N19: ='Estimation N'!U17 -> 0 | P19: Versement PER 154bis | Q19: ='Estimation N'!$X$17 -> 0
D20: Vous êtes nouvellement domicilié en France en…................................................................................................. | H20: ............................ | I20: ….................6QW | M20: Potentiel Madelin total | N20: =N21+N22 -> 0 | P20: Potentiel Madelin total | Q20: =Q21+Q22 -> 0
D21: Cotisations sur les nouveaux plans d'épargne retraite déduites des BIC, BNC, BA, Rem art62….....................6OS | H21: =IF(O13="Interprétation recalcul sur Revenu Brut Global",MAX(0,IF(IF(N18<N14,0,N18-N14)>0,N19,(N19+N18)-N14)),MAX(0,IF(IF(N18<N21,0,N18-N21)>0,N19,(N19+N18)-N21))) -> 0 | I21: 6OT | J21: =IF(O13="Interprétation recalcul sur Revenu Brut Global",MAX(0,IF(IF(Q18<Q14,0,Q18-Q14)>0,Q19,(Q19+Q18)-Q14)),MAX(0,IF(IF(Q18<Q21,0,Q18-Q21)>0,Q19,(Q19+Q18)-Q21))) -> 0 | M21: Enveloppe 15% | N21: =IF(N17<=Synthèse!$Q$10,0,IF(N17<=8*Synthèse!$Q$10,(N17-Synthèse!$Q$10)*0.15,((8*Synthèse!$Q$10)-Synthèse!$Q$10)*0.15)) -> 0 | O21: =IF((N18+N19)>=N21,0,N21-(N18+N19)) -> 0 | P21: Enveloppe 15% | Q21: =IF(Q17<=Synthèse!$Q$10,0,IF(Q17<=8*Synthèse!$Q$10,(Q17-Synthèse!$Q$10)*0.15,((8*Synthèse!$Q$10)-Synthèse!$Q$10)*0.15)) -> 0 | R21: =IF((Q18+Q19)>=Q21,0,Q21-(Q18+Q19)) -> 0
D22: Autres cotisations déduites des BIC, BNC, BA, rémun. art. 62 ou salaires …..................................................6QS | H22: =IF(O13="Interprétation recalcul sur Revenu Brut Global",'Estimation N'!U16+'Estimation N'!U15+IF(N18<N14,0,N18-N14),'Estimation N'!U16+'Estimation N'!U15+IF(N18<N21,0,N18-N21)) -> 0 | I22: 6QT | J22: =IF(O13="Interprétation recalcul sur Revenu Brut Global",'Estimation N'!X16+'Estimation N'!X15+IF(Q18<Q14,0,Q18-Q14),'Estimation N'!X16+'Estimation N'!X15+IF(Q18<Q21,0,Q18-Q21)) -> 0 | M22: Enveloppe 10% | N22: =IF(N16=0,0,IF(N17<=Synthèse!$Q$10,0.1*Synthèse!$Q$10,IF(N17<=8*Synthèse!$Q$10,N17*0.1,8*Synthèse!$Q$10*0.1))) -> 0 | O22: =IF(N16=0,0,IF(('Estimation N'!U15+'Estimation N'!U16)>=N22,IF((N18+N19)>N21,N22-(MAX(0,IF(IF(N18<N21,0,N18-N21)>0,N19,(N19+N18)-N21)))-('Estimation N'!U16+'Estimation N'!U15+IF(N18<N21,0,N18-N21)),0),N22-(MAX(0,IF(IF(N18<N21,0,N18-N21)>0,N19,(N19+N18)-N21)))-('Estimation N'!U16+'Estimation N'!U15+IF(N18<N21,0,N18-N21)))) -> 0 | P22: Enveloppe 10% | Q22: =IF(Q16=0,0,IF(Q17<=Synthèse!$Q$10,0.1*Synthèse!$Q$10,IF(Q17<=8*Synthèse!$Q$10,Q17*0.1,8*Synthèse!$Q$10*0.1))) -> 0 | R22: =IF(Q16=0,0,IF(('Estimation N'!X15+'Estimation N'!X16)>=Q22,IF((Q18+Q19)>Q21,Q22-(MAX(0,IF(IF(Q18<Q21,0,Q18-Q21)>0,Q19,(Q19+Q18)-Q21)))-('Estimation N'!X16+'Estimation N'!X15+IF(Q18<Q21,0,Q18-Q21)),0),Q22-(MAX(0,IF(IF(Q18<Q21,0,Q18-Q21)>0,Q19,(Q19+Q18)-Q21)))-('Estimation N'!X16+'Estimation N'!X15+IF(Q18<Q21,0,Q18-Q21)))) -> 0
M23: Potentiel Madelin restant : | O23: =O21+O22 -> 0 | P23: Potentiel Madelin restant | R23: =R21+R22 -> 0
M24: =IF(O23<0,"Réintégration fiscale à opérer","") | P24: =IF(R23<0,"Réintégration fiscale à opérer","")
D25: Simulation de l'AVIS IR
D27: AVIS D'IMPÔT | F27: =G13 -> 2027
D28: PLAFOND EPARGNE RETRAITE | H28: total cotiz | I28: =H16+H17 -> 0 | J28: =J16+J17 -> 0 | N28: report en avant déclarant 1 | Q28: Données pour calcul 2023
D29: Le plafond disponible pour la déduction des cotisations verées en …........ | G29: =F27 -> 2027 | H29: total plaf | I29: =I32+J32 -> 9420 | M29: =IF(AND('Pot ER Mode'!$G$13="Réaliser un versement N (et vérifier si le potentiel le permet)",'Pot ER Mode'!$H$15=Synthèse!$J$13),'Avis IR N-2'!L23,'Synthèse décla'!I35) -> 0 | N29: =IF(N32=0,0,IF(N32<=M29,0,N32-M29)) -> 0 | O29: =M29-N32 -> 0 | Q29: Déclarant 1 | R29: Déclarant 2
D30: pour la déclaration des revenus à souscrire en …...................................... | G30: =G29+1 -> 2028 | I30: =I32-H16-H17 -> 4710 | J30: =J32-J16-J17 -> 4710 | M30: =IF(AND('Pot ER Mode'!$G$13="Réaliser un versement N (et vérifier si le potentiel le permet)",'Pot ER Mode'!$H$15=Synthèse!$J$13),'Avis IR N-2'!L24,'Synthèse décla'!I36) -> 0 | N30: =IF(N29=0,0,IF(N29<=M30,0,N29-M30)) -> 0 | O30: =M30-N29 -> 0 | Q30: ='Estimation N'!H23+'Estimation N'!H24-'Estimation N'!H26+'Estimation N'!H29 -> 0 | R30: ='Estimation N'!K23+'Estimation N'!K24-'Estimation N'!K26+'Estimation N'!K29 -> 0
I31: Déclar. 1 | J31: Déclar. 2 | M31: =IF(AND('Pot ER Mode'!$G$13="Réaliser un versement N (et vérifier si le potentiel le permet)",'Pot ER Mode'!$H$15=Synthèse!$J$13),'Avis IR N-2'!L25,'Synthèse décla'!I37) -> 0 | N31: =IF(N30=0,0,IF(N30<=M31,0,N30-M31)) -> 0 | O31: =M31-N30 -> 0
D32: Plafond total de …...................................................................................... | G32: =G29-2 -> 2025 | I32: =IF(AND('Pot ER Mode'!G13="Réaliser un versement N (et vérifier si le potentiel le permet)",'Pot ER Mode'!H15=Synthèse!J13),'Avis IR N-2'!L28,'Synthèse décla'!I39) -> 4710 | J32: =IF('Estimation N'!G13=Données!L51,0,IF(AND('Pot ER Mode'!G13="Réaliser un versement N (et vérifier si le potentiel le permet)",'Pot ER Mode'!H15=Synthèse!J13),'Avis IR N-2'!M28,'Synthèse décla'!J39)) -> 4710 | M32: =IF(AND('Pot ER Mode'!$G$13="Réaliser un versement N (et vérifier si le potentiel le permet)",'Pot ER Mode'!$H$15=Synthèse!$J$13),'Avis IR N-2'!L26,'Synthèse décla'!I38) -> 4710 | N32: =IF(I34<=M32,IF(OR(J19="Non",J19=""),0,IF(J34>J32,I34+J34-J32-M32,I34-M32)),IF(J19="Non",I34-M32,IF(J34>J32,I34+J34-J32-M32,I34-M32))) -> 0 | O32: =M32-IF(OR(J19="Non",J19=""),I34,J33-J32+I34) -> 4710 | Q32: PASS
D33: Plafond après mutualisation…................................................................... | I33: =IF(AND(I28>=I32,J19="Oui",J30>=0),I32+IF(J30>=(I28-I32),I28-I32,J30),IF(J19="Oui",IF(J28>J32,IF(I30+J30>0,I29-J28,I28),I32),"")) | J33: =IF(AND(J28>=J32,J19="Oui",I30>=0),J32+IF(I30>=(J28-J32),J28-J32,I30),IF(J19="Oui",IF(I28>I32,IF(J30+I30>0,I29-I28,J28),J32),"")) | Q33: =Données!D50 -> 2019 | R33: =Données!E50 -> 40524
D34: Cotisations prises en compte pour …......................................................... | G34: =G32+1 -> 2026 | I34: =IF((H16+H17)>I32,IF(J19="Oui",I33,I32),(H16+H17)) -> 0 | J34: =IF('Estimation N'!G13=Données!L51,0,IF((J16+J17)>J32,IF(J19="Oui",J33,J32),(J16+J17))) -> 0 | N34: report en avant déclarant 2 | Q34: =Données!D51 -> 2020 | R34: =Données!E51 -> 41136
D35: Plafond non utilisé pour les revenus de ….................................................. | G35: =G32-1 -> 2024 | I35: =IF(O30>0,O30,0) -> 0 | J35: =IF('Estimation N'!G13=Données!L51,0,IF(O36>0,O36,0)) -> 0 | M35: =IF(AND('Pot ER Mode'!$G$13="Réaliser un versement N (et vérifier si le potentiel le permet)",'Pot ER Mode'!$H$15=Synthèse!$J$13),'Avis IR N-2'!M23,'Synthèse décla'!J35) -> 0 | N35: =IF(N38=0,0,IF(N38<=M35,0,N38-M35)) -> 0 | O35: =M35-N38 -> 0 | Q35: =Données!D52 -> 2021 | R35: =Données!E52 -> 41136
D36: Plafond non utilisé pour les revenus de ….................................................. | G36: =G35+1 -> 2025 | H36: ="+" -> + | I36: =IF(O31>0,O31,0) -> 0 | J36: =IF('Estimation N'!G13=Données!L51,0,IF(O37>0,O37,0)) -> 0 | M36: =IF(AND('Pot ER Mode'!$G$13="Réaliser un versement N (et vérifier si le potentiel le permet)",'Pot ER Mode'!$H$15=Synthèse!$J$13),'Avis IR N-2'!M24,'Synthèse décla'!J36) -> 0 | N36: =IF(N35=0,0,IF(N35<=M36,0,N35-M36)) -> 0 | O36: =M36-N35 -> 0 | Q36: =Données!D53 -> 2022 | R36: =Données!E53 -> 41136
D37: Plafond non utilisé pour les revenus de ….................................................. | G37: =G36+1 -> 2026 | H37: ="+" -> + | I37: =IF(O32>0,O32,0) -> 4710 | J37: =IF('Estimation N'!G13=Données!L51,0,IF(O38>0,O38,0)) -> 4710 | M37: =IF(AND('Pot ER Mode'!$G$13="Réaliser un versement N (et vérifier si le potentiel le permet)",'Pot ER Mode'!$H$15=Synthèse!$J$13),'Avis IR N-2'!M25,'Synthèse décla'!J37) -> 0 | N37: =IF(N36=0,0,IF(N36<=M37,0,N36-M37)) -> 0 | O37: =M37-N36 -> 0 | Q37: =Données!D54 -> 2023 | R37: =Données!E54 -> 43992
